Workbook

Sheet design.old
C3: Construct | D3: Compliance Progress and Breach Prevention | H3: Organizational and Industry Dynamics | I3: Data and Breach Analysis
C4: Research Question | D4: 1. What differences exist in compliance status and breach prevention measures between companies that experienced breaches before and after achieving compliance? | H4: 2. How do breach occurrences and data classification vary across industries, company statuses, and acquisition statuses? | I4: 3. How do the types of data compromised and the root causes of breach differ between compliant and non-compliant companies?
C5: Hypothesis | D5: H01. There is no significant difference in compliance status or breach prevention measures between companies that experienced breaches before and after achieving compliance. | H5: H02. Breach occurrences and data classifications do not significantly differ across industries, company statuses, or acquisition statuses. | I5: H03. There is no significant difference in the types of data compromised or the root causes of breaches between compliant and non-compliant companies.
D6: Ha1. There is a significant difference in compliance status or breach prevention measures between companies that experienced breaches before and after achieving compliance. | H6: Ha2. Breach occurrences and data classifications significantly differ across industries, company statuses, and acquisition statuses. | I6: Ha3. There is a significant difference in the types of data compromised and the root causes of breaches between compliant and non-compliant companies.
C7: Variable | D7: Independent Variable: compliance status and breach prevention measures Dependent Variable: differences in company outcomes related to breaches before and after achieving compliance | H7: Independent Variable: industries, company statuses and acquisition statuses Dependent Variable: breach occurrences and classification of data | I7: Independent Variable: compliance status (compliant vs non-compliant companies) Dependent Variable: types of data compromised and root causes of breaches
C8: Test | D8: Paired T-test (Inferential); Mean, median, standard deviation, frequency distributions (Descriptive) | H8: Paired T-test (Inferential); Mean, median, standard deviation, frequency distributions (Descriptive) | I8: Paired T-test (Inferential); Mean, median, standard deviation, frequency distributions (Descriptive)
B9: Instrument | D9: Category
B10: Survey Question | C10: Likert Scale | D10: Compliance Status (adherence to industry standards and regulations) | E10: Company Status (public/private) | F10: Industry Status (type of industry) | G10: Acquisition Status (acquired/non-acquired) | H10: Data Classification (sensitive data types) | I10: Root Cause Analysis (cause of breach) | J10: Training and Enforcement (compliance training for employees)
A11: 1 | B11: The company's adherence to all relevant industry standards and regulations. | C11: 0 - Not Effective, 5 - Most Effective | D11: ✓
A12: 2 | B12: The company's public or private status impacts its approach to compliance and data protection. | C12: 0 - Not Effective, 5 - Most Effective | E12: ✓
A13: 3 | B13: The company's industry type influences its compliance requirements and challenges. | C13: 0 - Not Effective, 5 - Most Effective | F13: ✓
A14: 4 | B14: The company's acquisition status affects its compliance practices (having either been acquired or not acquiired by another entity). | C14: 0 - Not Effective, 5 - Most Effective | G14: ✓
A15: 5 | B15: The company's data classification system effectiveness in identifying and protecting sensitive information. | C15: 0 - Not Effective, 5 - Most Effective | H15: ✓
A16: 6 | B16: When a data breach occurs, the company's root cause analysis thoroughness in identifying and improving compliance failures. | C16: 0 - Not Effective, 5 - Most Effective | I16: ✓
A17: 7 | B17: The company's policies and procedures effectiveness in ensuring third-party vendors comply with relevant regulations and standards. | C17: 0 - Not Effective, 5 - Most Effective | J17: ✓
B19: Theoretical Frameworks
B20: Institutional Theory: Examines how regulatory requirements, industry standards, and societal expectations shape companies' compliance status and breach risk.
B21: Transaction Cost Economics (TCE) Theory: Analyzes the costs and benefits of cybersecurity strategies and compliance measures, and their impact on breach risk.
B22: Expected Outcomes
B23: Understanding differences in compliance, public status, and acquisition status in relation to breaches.

Sheet INF STATS
C4: GDPR Before and After
C40: Acquisitions Before and After
C72: Public Before and After
C106: data classification
C202: Root Cause and GDPR

Sheet DIFF STATS
BR3: Data Classification (Sensitive)
B4: Sample Set | E4: Breaches | I4: Causes | M4: Vulnerabilities | Q4: Breaches and Acquisitions | V4: Descriptive Stats | AB4: Breaches and Going Public | AG4: Descriptive Stats | AM4: Industry | AQ4: Breaches and Compliance | BB4: Compliance | BC4: Count of Companies | BD4: % of Companies | BE4: PII | BF4: PII % | BG4: PHI | BH4: PHI % | BI4: PCI | BJ4: PCI % | BR4: PII | BS4: 112 | BT4: =BS4/SUM($BS$4:$BS$6) -> 0.68292683
B5: Name | C5: (All) | E5: Row Labels | F5: Count of Name | I5: Row Labels | J5: Count of Industry | M5: Row Labels | N5: Count of Industry | Q5: Row Labels | R5: Count of B2A Years | S5: % | T5: AVG Yrs | V5: Breach before Acquisition | Y5: Breach after Acquisition | AB5: Row Labels | AC5: Count of B2P Years | AD5: % | AE5: AVG Yrs | AG5: Breach before going Public | AJ5: Breach after going Public | AM5: Row Labels | AN5: Count of Industry | AQ5: Row Labels | AR5: Count of GDPR | AU5: Breach before GDPR | AX5: Breach after GDPR | BB5: GDPR | BC5: 179 | BD5: =BC5/GETPIVOTDATA("Name",$B$7) -> 0.88613861 | BE5: =COUNTIFS(SAMPLES!$R$3:$R$204,"yes",SAMPLES!AB3:AB204,"yes") -> 97 | BF5: =BE5/SUM($BE$5:$BE$13) -> 0.58787879 | BG5: =COUNTIFS(SAMPLES!$R$3:$R$204,"yes",SAMPLES!AF3:AF204,"yes") -> 22 | BH5: =BG5/SUM($BG$5:$BG$13) -> 0.42307692 | BI5: =COUNTIFS(SAMPLES!$R$3:$R$204,"yes",SAMPLES!AD3:AD204,"yes") -> 17 | BJ5: =BI5/SUM($BI$5:$BI$13) -> 0.53125 | BR5: PHI | BS5: 32 | BT5: =BS5/SUM($BS$4:$BS$6) -> 0.19512195
E6: 2017 | F6: 11 | I6: System Vulnerability Exploit | J6: 27 | K6: =GETPIVOTDATA("Industry",$I$5,"How the Breach Happened","System Vulnerability Exploit")/GETPIVOTDATA("Industry",$I$5) -> 0.13366337 | M6: System Vulnerability Exploit | N6: 27 | Q6: after | R6: 27 | S6: =GETPIVOTDATA("B2A Years",$Q$5,"B2A","after")/GETPIVOTDATA("B2A Years",$Q$5) -> 0.5625 | T6: =AVERAGEIF(SAMPLES!AP3:AP204,"after",SAMPLES!AQ3:AQ204) -> 7.962963 | AB6: after | AC6: 78 | AD6: =GETPIVOTDATA("B2P Years",$AB$5,"B2P","after")/GETPIVOTDATA("B2P Years",$AB$5) -> 0.93975904 | AE6: =AVERAGEIF(SAMPLES!AR3:AR204,"after",SAMPLES!AS3:AS204) -> 24.5 | AM6: Technology | AN6: 44 | AO6: =GETPIVOTDATA("Industry",$AM$5,"Industry","Technology")/GETPIVOTDATA("Industry",$AM$5) -> 0.21782178 | AQ6: yes | AR6: 179 | BB6: HIPAA | BC6: 34 | BD6: =BC6/GETPIVOTDATA("Name",$B$7) -> 0.16831683 | BE6: =COUNTIFS(SAMPLES!$W$3:$W$204,"yes",SAMPLES!AB3:AB204,"yes") -> 16 | BF6: =BE6/SUM($BE$5:$BE$13) -> 0.096969697 | BG6: =COUNTIFS(SAMPLES!$W$3:$W$204,"yes",SAMPLES!AF3:AF204,"yes") -> 27 | BH6: =BG6/SUM($BG$5:$BG$13) -> 0.51923077 | BI6: =COUNTIFS(SAMPLES!$W$3:$W$204,"yes",SAMPLES!AD3:AD204,"yes") -> 0 | BJ6: =BI6/SUM($BI$5:$BI$13) -> 0 | BR6: PCI | BS6: 20 | BT6: =BS6/SUM($BS$4:$BS$6) -> 0.12195122
B7: Count of Name | E7: 2018 | F7: 16 | I7: Ransomware | J7: 22 | K7: =GETPIVOTDATA("Industry",$I$5,"How the Breach Happened","Ransomware")/GETPIVOTDATA("Industry",$I$5) -> 0.10891089 | M7: API Vulnerability Exploit | N7: 5 | Q7: before | R7: 14 | S7: =GETPIVOTDATA("B2A Years",$Q$5,"B2A","before")/GETPIVOTDATA("B2A Years",$Q$5) -> 0.29166667 | T7: =AVERAGEIF(SAMPLES!AP3:AP204,"before",SAMPLES!AQ3:AQ204) -> 1.2142857 | V7: Mean | W7: 1.2142857 | Y7: Mean | Z7: 7.962963 | AB7: before | AC7: 4 | AD7: =GETPIVOTDATA("B2P Years",$AB$5,"B2P","before")/GETPIVOTDATA("B2P Years",$AB$5) -> 0.048192771 | AE7: =AVERAGEIF(SAMPLES!AR3:AR204,"before",SAMPLES!AS3:AS204) -> 1.5 | AG7: Mean | AH7: 1.5 | AJ7: Mean | AK7: 24.5 | AM7: Healthcare | AN7: 27 | AO7: =GETPIVOTDATA("Industry",$AM$5,"Industry","Healthcare")/GETPIVOTDATA("Industry",$AM$5) -> 0.13366337 | AQ7: Grand Total | AR7: 179 | AU7: Mean | AV7: 0.03960396 | AX7: Mean | AY7: 0.84653465 | BB7: PCI | BC7: 23 | BD7: =BC7/GETPIVOTDATA("Name",$B$7) -> 0.11386139 | BE7: =COUNTIFS(SAMPLES!$T$3:$T$204,"yes",SAMPLES!AB3:AB204,"yes") -> 12 | BF7: =BE7/SUM($BE$5:$BE$13) -> 0.072727273 | BG7: =COUNTIFS(SAMPLES!$T$3:$T$204,"yes",SAMPLES!AF3:AF204,"yes") -> 2 | BH7: =BG7/SUM($BG$5:$BG$13) -> 0.038461538 | BI7: =COUNTIFS(SAMPLES!$T$3:$T$204,"yes",SAMPLES!AD3:AD204,"yes") -> 8 | BJ7: =BI7/SUM($BI$5:$BI$13) -> 0.25
B8: 202 | E8: 2019 | F8: 29 | I8: Phishing | J8: 19 | K8: =GETPIVOTDATA("Industry",$I$5,"How the Breach Happened","Phishing")/GETPIVOTDATA("Industry",$I$5) -> 0.094059406 | M8: Software Vulnerability Exploit | N8: 4 | Q8: same year | R8: 7 | S8: =GETPIVOTDATA("B2A Years",$Q$5,"B2A","same year")/GETPIVOTDATA("B2A Years",$Q$5) -> 0.14583333 | T8: =AVERAGEIF(SAMPLES!AP3:AP204,"same year",SAMPLES!AQ3:AQ204) -> 0 | V8: Standard Error | W8: 0.15472668 | Y8: Standard Error | Z8: 1.4622325 | AB8: same year | AC8: 1 | AD8: =GETPIVOTDATA("B2P Years",$AB$5,"B2P","same year")/GETPIVOTDATA("B2P Years",$AB$5) -> 0.012048193 | AE8: =AVERAGEIF(SAMPLES!AR3:AR204,"same year",SAMPLES!AS3:AS204) -> 0 | AG8: Standard Error | AH8: 0.28867513 | AJ8: Standard Error | AK8: 2.5139471 | AM8: Social Media | AN8: 23 | AO8: =GETPIVOTDATA("Industry",$AM$5,"Industry","Social Media")/GETPIVOTDATA("Industry",$AM$5) -> 0.11386139 | AU8: Standard Error | AV8: 0.013756136 | AX8: Standard Error | AY8: 0.025423158 | BB8: CCPA | BC8: 22 | BD8: =BC8/GETPIVOTDATA("Name",$B$7) -> 0.10891089 | BE8: =COUNTIFS(SAMPLES!$Y$3:$Y$204,"yes",SAMPLES!AB3:AB204,"yes") -> 16 | BF8: =BE8/SUM($BE$5:$BE$13) -> 0.096969697 | BG8: =COUNTIFS(SAMPLES!$Y$3:$Y$204,"yes",SAMPLES!AF3:AF204,"yes") -> 0 | BH8: =BG8/SUM($BG$5:$BG$13) -> 0 | BI8: =COUNTIFS(SAMPLES!$Y$3:$Y$204,"yes",SAMPLES!AD3:AD204,"yes") -> 2 | BJ8: =BI8/SUM($BI$5:$BI$13) -> 0.0625 | BR8: Data Classification (Other)
E9: 2020 | F9: 52 | I9: Unsecured database | J9: 18 | K9: =GETPIVOTDATA("Industry",$I$5,"How the Breach Happened","Misconfigured Database")/GETPIVOTDATA("Industry",$I$5) -> 0.089108911 | M9: Database Vulnerability Exploit | N9: 3 | Q9: Grand Total | R9: 48 | V9: Median | W9: 1 | Y9: Median | Z9: 5 | AB9: Grand Total | AC9: 83 | AG9: Median | AH9: 1.5 | AJ9: Median | AK9: 19 | AM9: Telecommunications | AN9: 13 | AO9: =GETPIVOTDATA("Industry",$AM$5,"Industry","Telecommunications")/GETPIVOTDATA("Industry",$AM$5) -> 0.064356436 | AU9: Median | AV9: 0 | AX9: Median | AY9: 1 | BB9: ISO | BC9: 19 | BD9: =BC9/GETPIVOTDATA("Name",$B$7) -> 0.094059406 | BE9: =COUNTIFS(SAMPLES!$S$3:$S$204,"yes",SAMPLES!AB3:AB204,"yes") -> 10 | BF9: =BE9/SUM($BE$5:$BE$13) -> 0.060606061 | BG9: =COUNTIFS(SAMPLES!$S$3:$S$204,"yes",SAMPLES!AF3:AF204,"yes") -> 0 | BH9: =BG9/SUM($BG$5:$BG$13) -> 0 | BI9: =COUNTIFS(SAMPLES!$S$3:$S$204,"yes",SAMPLES!AD3:AD204,"yes") -> 1 | BJ9: =BI9/SUM($BI$5:$BI$13) -> 0.03125 | BR9: Company Data | BS9: 47 | BT9: =BS9/SUM($BS$9:$BS$10) -> 0.4159292
E10: 2021 | F10: 45 | I10: Misconfigured Database | J10: 18 | K10: =GETPIVOTDATA("Industry",$I$5,"How the Breach Happened","Unsecured database")/GETPIVOTDATA("Industry",$I$5) -> 0.089108911 | M10: Network Vulnerability Exploit | N10: 2 | V10: Mode | W10: 1 | Y10: Mode | Z10: 2 | AG10: Mode | AH10: 1 | AJ10: Mode | AK10: 7 | AM10: Retail | AN10: 12 | AO10: =GETPIVOTDATA("Industry",$AM$5,"Industry","Retail")/GETPIVOTDATA("Industry",$AM$5) -> 0.059405941 | AQ10: Row Labels | AR10: Count of B2GDPR | AS10: % | AT10: AVG Yrs | AU10: Mode | AV10: 0 | AX10: Mode | AY10: 1 | BB10: SOC | BC10: 10 | BD10: =BC10/GETPIVOTDATA("Name",$B$7) -> 0.04950495 | BE10: =COUNTIFS(SAMPLES!$X$3:$X$204,"yes",SAMPLES!AB3:AB204,"yes") -> 6 | BF10: =BE10/SUM($BE$5:$BE$13) -> 0.036363636 | BG10: =COUNTIFS(SAMPLES!$X$3:$X$204,"yes",SAMPLES!AF3:AF204,"yes") -> 0 | BH10: =BG10/SUM($BG$5:$BG$13) -> 0 | BI10: =COUNTIFS(SAMPLES!$X$3:$X$204,"yes",SAMPLES!AD3:AD204,"yes") -> 0 | BJ10: =BI10/SUM($BI$5:$BI$13) -> 0 | BR10: Technical Data | BS10: 66 | BT10: =BS10/SUM($BS$9:$BS$10) -> 0.5840708
E11: 2022 | F11: 25 | I11: Third Party | J11: 12 | K11: =GETPIVOTDATA("Industry",$I$5,"How the Breach Happened","Third Party")/GETPIVOTDATA("Industry",$I$5) -> 0.059405941 | M11: Software Vulnerability Exploit (state sponsored) | N11: 1 | V11: Standard Deviation | W11: 0.57893422 | Y11: Standard Deviation | Z11: 7.5979829 | AG11: Standard Deviation | AH11: 0.57735027 | AJ11: Standard Deviation | AK11: 22.20258 | AM11: Entertainment | AN11: 10 | AO11: =GETPIVOTDATA("Industry",$AM$5,"Industry","Entertainment")/GETPIVOTDATA("Industry",$AM$5) -> 0.04950495 | AQ11: after | AR11: 155 | AS11: =GETPIVOTDATA("B2GDPR",$AQ$10,"B2GDPR","after")/GETPIVOTDATA("B2GDPR",$AQ$10) -> 0.86592179 | AT11: =AVERAGEIF(SAMPLES!AT3:AT204,"after",SAMPLES!AU3:AU204) -> 2.6580645 | AU11: Standard Deviation | AV11: 0.19551143 | AX11: Standard Deviation | AY11: 0.36133097 | BB11: SOX | BC11: 6 | BD11: =BC11/GETPIVOTDATA("Name",$B$7) -> 0.02970297 | BE11: =COUNTIFS(SAMPLES!$U$3:$U$204,"yes",SAMPLES!AB3:AB204,"yes") -> 3 | BF11: =BE11/SUM($BE$5:$BE$13) -> 0.018181818 | BG11: =COUNTIFS(SAMPLES!$U$3:$U$204,"yes",SAMPLES!AF3:AF204,"yes") -> 1 | BH11: =BG11/SUM($BG$5:$BG$13) -> 0.019230769 | BI11: =COUNTIFS(SAMPLES!$U$3:$U$204,"yes",SAMPLES!AD3:AD204,"yes") -> 1 | BJ11: =BI11/SUM($BI$5:$BI$13) -> 0.03125
E12: 2023 | F12: 17 | I12: Data Scraping | J12: 11 | K12: =GETPIVOTDATA("Industry",$I$5,"How the Breach Happened","Data Scraping")/GETPIVOTDATA("Industry",$I$5) -> 0.054455446 | M12: Vulnerability in website and mobile app | N12: 1 | V12: Sample Variance | W12: 0.33516484 | Y12: Sample Variance | Z12: 57.729345 | AG12: Sample Variance | AH12: 0.33333333 | AJ12: Sample Variance | AK12: 492.95455 | AM12: Financial Services | AN12: 10 | AO12: =GETPIVOTDATA("Industry",$AM$5,"Industry","Financial Services")/GETPIVOTDATA("Industry",$AM$5) -> 0.04950495 | AQ12: before | AR12: 8 | AS12: =GETPIVOTDATA("B2GDPR",$AQ$10,"B2GDPR","before")/GETPIVOTDATA("B2GDPR",$AQ$10) -> 0.044692737 | AT12: =AVERAGEIF(SAMPLES!AT3:AT204,"before",SAMPLES!AU3:AU204) -> 1 | AU12: Sample Variance | AV12: 0.038224718 | AX12: Sample Variance | AY12: 0.13056007 | BB12: GLBA | BC12: 5 | BD12: =BC12/GETPIVOTDATA("Name",$B$7) -> 0.024752475 | BE12: =COUNTIFS(SAMPLES!$V$3:$V$204,"yes",SAMPLES!AB3:AB204,"yes") -> 3 | BF12: =BE12/SUM($BE$5:$BE$13) -> 0.018181818 | BG12: =COUNTIFS(SAMPLES!$V$3:$V$204,"yes",SAMPLES!AF3:AF204,"yes") -> 0 | BH12: =BG12/SUM($BG$5:$BG$13) -> 0 | BI12: =COUNTIFS(SAMPLES!$V$3:$V$204,"yes",SAMPLES!AD3:AD204,"yes") -> 3 | BJ12: =BI12/SUM($BI$5:$BI$13) -> 0.09375
E13: 2024 | F13: 7 | I13: Credential Stuffing | J13: 8 | K13: =GETPIVOTDATA("Industry",$I$5,"How the Breach Happened","Credential Stuffing")/GETPIVOTDATA("Industry",$I$5) -> 0.03960396 | M13: Cloud Storage Vulnerability Exploit | N13: 1 | V13: Kurtosis | W13: 7.6791185 | Y13: Kurtosis | Z13: -0.1384306 | AG13: Kurtosis | AH13: -6 | AJ13: Kurtosis | AK13: 5.0132951 | AM13: Insurance | AN13: 7 | AO13: =GETPIVOTDATA("Industry",$AM$5,"Industry","Insurance")/GETPIVOTDATA("Industry",$AM$5) -> 0.034653465 | AQ13: same year | AR13: 16 | AS13: =GETPIVOTDATA("B2GDPR",$AQ$10,"B2GDPR","same year")/GETPIVOTDATA("B2GDPR",$AQ$10) -> 0.089385475 | AT13: =AVERAGEIF(SAMPLES!AT3:AT204,"same year",SAMPLES!AU3:AU204) -> 0 | AU13: Kurtosis | AV13: 20.832898 | AX13: Kurtosis | AY13: 1.7704937 | BB13: RAMP | BC13: 3 | BD13: =BC13/GETPIVOTDATA("Name",$B$7) -> 0.014851485 | BE13: =COUNTIFS(SAMPLES!$Z$3:$Z$204,"yes",SAMPLES!AB3:AB204,"yes") -> 2 | BF13: =BE13/SUM($BE$5:$BE$13) -> 0.012121212 | BG13: =COUNTIFS(SAMPLES!$Z$3:$Z$204,"yes",SAMPLES!AF3:AF204,"yes") -> 0 | BH13: =BG13/SUM($BG$5:$BG$13) -> 0 | BI13: =COUNTIFS(SAMPLES!$Z$3:$Z$204,"yes",SAMPLES!AD3:AD204,"yes") -> 0 | BJ13: =BI13/SUM($BI$5:$BI$13) -> 0
E14: Grand Total | F14: 202 | I14: Unauthorized Access | J14: 7 | K14: =GETPIVOTDATA("Industry",$I$5,"How the Breach Happened","Unauthorized Access")/GETPIVOTDATA("Industry",$I$5) -> 0.034653465 | M14: Web Application Vulnerability Exploit | N14: 1 | V14: Skewness | W14: 2.8033423 | Y14: Skewness | Z14: 1.1714325 | AG14: Skewness | AH14: 0 | AJ14: Skewness | AK14: 1.7841799 | AM14: Marketing | AN14: 6 | AO14: =GETPIVOTDATA("Industry",$AM$5,"Industry","Marketing")/GETPIVOTDATA("Industry",$AM$5) -> 0.02970297 | AQ14: Grand Total | AR14: 179 | AU14: Skewness | AV14: 4.7567552 | AX14: Skewness | AY14: -1.937282
I15: API Vulnerability Exploit | J15: 5 | K15: =GETPIVOTDATA("Industry",$I$5,"How the Breach Happened","API Vulnerability Exploit")/GETPIVOTDATA("Industry",$I$5) -> 0.024752475 | M15: Vulnerability in legacy file transfer system | N15: 1 | Q15: Breaches and Acquisitions | V15: Range | W15: 2 | Y15: Range | Z15: 24 | AG15: Range | AH15: 1 | AJ15: Range | AK15: 127 | AM15: Hospitality | AN15: 5 | AO15: =GETPIVOTDATA("Industry",$AM$5,"Industry","Hospitality")/GETPIVOTDATA("Industry",$AM$5) -> 0.024752475 | AU15: Range | AV15: 1 | AX15: Range | AY15: 1
I16: Unspecified | J16: 5 | M16: Grand Total | N16: 46 | O16: =GETPIVOTDATA("Industry",$M$5)/GETPIVOTDATA("Industry",$I$5) -> 0.22772277 | Q16: Row Labels | R16: Count of Acquired | V16: Minimum | W16: 1 | Y16: Minimum | Z16: 1 | AB16: Row Labels | AC16: Count of Is Public | AG16: Minimum | AH16: 1 | AJ16: Minimum | AK16: 1 | AM16: Financial Technology (FinTech) | AN16: 5 | AU16: Minimum | AV16: 0 | AX16: Minimum | AY16: 0
I17: Malware | J17: 4 | Q17: No | R17: 154 | S17: =GETPIVOTDATA("Acquired",$Q$16,"Acquired","No")/GETPIVOTDATA("Acquired",$Q$16) -> 0.76237624 | V17: Maximum | W17: 3 | Y17: Maximum | Z17: 25 | AB17: No | AC17: 119 | AD17: =GETPIVOTDATA("Is Public",$AB$16,"Is Public","No")/GETPIVOTDATA("Is Public",$AB$16) -> 0.58910891 | AG17: Maximum | AH17: 2 | AJ17: Maximum | AK17: 128 | AM17: Cybersecurity | AN17: 4 | AU17: Maximum | AV17: 1 | AX17: Maximum | AY17: 1
I18: Supply Chain Attack | J18: 4 | Q18: Yes | R18: 48 | S18: =GETPIVOTDATA("Acquired",$Q$16,"Acquired","Yes")/GETPIVOTDATA("Acquired",$Q$16) -> 0.23762376 | V18: Sum | W18: 17 | Y18: Sum | Z18: 215 | AB18: Yes | AC18: 83 | AD18: =GETPIVOTDATA("Is Public",$AB$16,"Is Public","Yes")/GETPIVOTDATA("Is Public",$AB$16) -> 0.41089109 | AG18: Sum | AH18: 6 | AJ18: Sum | AK18: 1911 | AM18: Airlines | AN18: 4 | AU18: Sum | AV18: 8 | AX18: Sum | AY18: 171
I19: Social Engineering | J19: 4 | Q19: Grand Total | R19: 202 | V19: Count | W19: 14 | Y19: Count | Z19: 27 | AB19: Grand Total | AC19: 202 | AG19: Count | AH19: 4 | AJ19: Count | AK19: 78 | AM19: Electronics | AN19: 4 | AU19: Count | AV19: 202 | AX19: Count | AY19: 202
B20: Row Labels | I20: Software Vulnerability Exploit | J20: 4 | M20: root cause | AM20: Automotive | AN20: 3
B21: 179 | I21: Database Vulnerability Exploit | J21: 3 | AM21: Government | AN21: 3
B22: yes | I22: Unsecured AWS S3 bucket | J22: 3 | M22: Mean | N22: 5.4594595 | Q22: Avg Yrs Before | R22: Avg Yrs During | S22: Avg Yrs After | AB22: Avg Yrs Before | AC22: Avg Yrs During | AD22: Avg yrs After | AM22: Transportation | AN22: 3
B23: (blank) | I23: Misconfigured Cloud Storage | J23: 3 | M23: Standard Error | N23: 1.1214497 | Q23: =AVERAGEIFS(SAMPLES!AQ3:AQ204,SAMPLES!AP3:AP204,"before") -> 1.2142857 | R23: =AVERAGEIFS(SAMPLES!AQ3:AQ204,SAMPLES!AP3:AP204,"same year") -> 0 | S23: =AVERAGEIFS(SAMPLES!AQ3:AQ204,SAMPLES!AP3:AP204,"after") -> 7.962963 | AB23: =AVERAGEIFS(SAMPLES!AS3:AS204,SAMPLES!AR3:AR204,"before") -> 1.5 | AC23: =AVERAGEIFS(SAMPLES!AS3:AS204,SAMPLES!AR3:AR204,"same year") -> 0 | AD23: =AVERAGEIFS(SAMPLES!AS3:AS204,SAMPLES!AR3:AR204,"after") -> 24.5 | AM23: Food Delivery | AN23: 3
B24: Grand Total | I24: Unsecured Cloud Storage | J24: 2 | M24: Median | N24: 2 | AM24: Education | AN24: 2
I25: Misonfigured Server | J25: 2 | M25: Mode | N25: 1 | AM25: Conglomerate | AN25: 1
I26: Insider Threat | J26: 2 | M26: Standard Deviation | N26: 6.8215125 | AM26: Sports | AN26: 1
I27: Social engineering via forged legal requests | J27: 2 | M27: Sample Variance | N27: 46.533033 | AM27: Analytics | AN27: 1
I28: Network Vulnerability Exploit | J28: 2 | M28: Kurtosis | N28: 2.5253418 | AM28: Professional Services | AN28: 1
I29: Unsecured Server | J29: 2 | M29: Skewness | N29: 1.8463504 | AM29: Humanitarian Services | AN29: 1
I30: Unauthorized access by a former employee | J30: 1 | M30: Range | N30: 26 | AM30: Travel & Leisure | AN30: 1
I31: Certificate Exploit | J31: 1 | M31: Minimum | N31: 1 | AM31: Design Software | AN31: 1
I32: Software Vulnerability Exploit (state sponsored) | J32: 1 | M32: Maximum | N32: 27 | AM32: Aerospace | AN32: 1
I33: Misconfigured Firewall | J33: 1 | M33: Sum | N33: 202 | AM33: Food & Beverage | AN33: 1
I34: Vulnerability in website and mobile app | J34: 1 | M34: Count | N34: 37 | AM34: Consumer Goods | AN34: 1
I35: Cloud Storage Vulnerability Exploit | J35: 1 | AM35: Media | AN35: 1
I36: Two Factor Authentication Exploit | J36: 1 | AM36: Video Games | AN36: 1
I37: Vulnerability in legacy file transfer system | J37: 1 | AM37: Food Processing | AN37: 1
I38: Skimming attack | J38: 1 | AM38: Fundraising | AN38: 1
I39: Web Application Vulnerability Exploit | J39: 1 | AM39: (blank)
I40: Point-of-sale System Compromise | J40: 1 | AM40: Grand Total | AN40: 202
I41: Compromised employee accounts | J41: 1
I42: Source Code Exploit | J42: 1
...

Sheet SAMPLES
A1: COMPANY | M1: DATA BREACH | Q1: COMPLIANCE | AA1: DATA CLASSIFICATION | AM1: YEARS MEASUREMENTS
A2: Name | B2: Industry | C2: Acquired | D2: Year Acquired | E2: Acquired by | F2: Is Inactive | G2: Date Inactive | H2: Is Public | I2: Year Public | J2: Net Worth | K2: Exchange | L2: Symbol | M2: Year Breached | N2: Records Exposed | O2: Type of Data Breached | P2: How the Breach Happened | Q2: Compliance Standards | R2: GDPR | S2: ISO | T2: PCI | U2: SOX | V2: GLBA | W2: HIPAA | X2: SOC | Y2: CCPA | Z2: RAMP | AA2: PII | AB2: is PII | AC2: PCI | AD2: is PCI | AE2: PHI | AF2: is PHI | AG2: Company Data | AH2: is Company | AI2: Technical Data | AJ2: is Technical | AK2: not disclosed | AL2: is not disclosed | AM2: acquired | AN2: public | AO2: breach | AP2: B2A | AQ2: B2A Years | AR2: B2P | AS2: B2P Years | AT2: B2GDPR | AU2: B2GDPR Yrs | AV2: B2D | AW2: RCA Vuln | AX2: RCA2GDPR | AY2: Company Name | AZ2: Compliance URL (subject to change)
A3: Aadhaar | B3: =VLOOKUP(A3,industry!A:B,2,FALSE) -> Government | C3: =VLOOKUP(A3,acquisitions!A:D,2,FALSE) -> No | D3: =VLOOKUP(A3,acquisitions!A:D,4,FALSE) -> N/A | E3: =VLOOKUP(A3,acquisitions!A:D,3,FALSE) -> N/A | F3: =VLOOKUP(A3,acquisitions!I:K,2,FALSE) -> Active | G3: =IF(F3="active","",VLOOKUP(A3,acquisitions!I:K,3,FALSE)) | H3: =VLOOKUP(A3,public!A:D,2,FALSE) -> No | I3: =VLOOKUP(A3,public!J:K,2,FALSE) -> #N/A | K3: =VLOOKUP(A3,public!A:D,3,FALSE) -> N/A | L3: =VLOOKUP(A3,public!A:D,4,FALSE) -> N/A | M3: 2018 | N3: 1100000000 | O3: Personal Identification Information | P3: Credential Stuffing | Q3: ISO 27001, GDPR | R3: yes | S3: yes | AA3: =COUNTIF(O3,"=*personal*")+COUNTIF(O3,"=*ssn*")++COUNTIF(O3,"=*license*")+COUNTIF(O3,"=*email*")+COUNTIF(O3,"=*vehic*")+COUNTIF(O3,"=*profile*")+COUNTIF(O3,"=*account*")+COUNTIF(O3,"=*image*")+COUNTIF(O3,"=*phone*")+COUNTIF(O3,"=*photo*") -> 1 | AB3: =IF(AA3>0,"yes","") -> yes | AC3: =COUNTIF(O3,"=*financ*")+COUNTIF(O3,"=*card*")+COUNTIF(O3,"=*crypto*")+COUNTIF(O3,"=*bank*")+COUNTIF(O3,"=*pay*") -> 0 | AD3: =IF(AC3>0,"yes","") | AE3: =COUNTIF(O3,"=*health*")+COUNTIF(O3,"=*bio*")+COUNTIF(O3,"=*medic*")+COUNTIF(O3,"=*patient*") -> 0 | AF3: =IF(AE3>0,"yes","") | AG3: =COUNTIF(O3,"=*customer*")+COUNTIF(O3,"=*employee*")+COUNTIF(O3,"=*guest*")+COUNTIF(O3,"=*passen*")+COUNTIF(O3,"=*applicant*")+COUNTIF(O3,"=*client*") -> 0 | AH3: =IF(AG3>0,"yes","") | AI3: =COUNTIF(O3,"=*user*")+COUNTIF(O3,"=*code*")+COUNTIF(O3,"=*software*")+COUNTIF(O3,"=*system*")+COUNTIF(O3,"=*text*")+COUNTIF(O3,"=*api*")+COUNTIF(O3,"=*cyber*") -> 0 | AJ3: =IF(AI3>0,"yes","") | AK3: =COUNTIF(O3,"=*not disclosed*") -> 0 | AL3: =IF(AK3>0,"yes","") | AM3: =IF(C3="yes",D3,"") | AN3: =IF(H3="yes",I3,"") | AO3: =M3 -> 2018 | AP3: =IF(C3="yes",IF(AO3=D3,"same year",IF(AO3<D3,"before",IF(AO3>D3,"after"))),"") | AQ3: =IF(C3="yes",IF(AP3="before",D3-AO3,IF(AP3="after",AO3-D3,IF(AP3="same year",0))),"") | AR3: =IF(H3="yes",IF(AO3=I3,"same year",IF(AO3<I3,"before",IF(AO3>I3,"after"))),"") | AS3: =IF(H3="yes",IF(AR3="same year",0,IF(AR3="before",I3-AO3,IF(AR3="after",AO3-I3))),"") | AT3: =IF(R3="yes",IF(AO3<2018,"before",IF(AO3=2018,"same year",IF(AO3>2018,"after"))),"") -> same year | AU3: =IF(R3="yes",IF(AT3="before",2018-AO3,IF(AT3="after",AO3-2018,IF(AT3="same year",0))),"") -> 0 | AV3: =IF(F3="defunct",IF(AO3=G3,"same year",IF(AO3<G3,"before",IF(AO3>=G3,"after"))),"") | AW3: =COUNTIF(P3,"=*vuln*") -> 0 | AX3: =COUNTIF(R3,"=yes") -> 1 | AY3: Aadhaar | AZ3: =VLOOKUP(A3,certs!U:V,2,FALSE) -> https://myaadhaar.uidai.gov.in/
A4: Accellion | B4: =VLOOKUP(A4,industry!A:B,2,FALSE) -> Technology | C4: =VLOOKUP(A4,acquisitions!A:D,2,FALSE) -> Yes | D4: =VLOOKUP(A4,acquisitions!A:D,4,FALSE) -> 2021 | E4: =VLOOKUP(A4,acquisitions!A:D,3,FALSE) -> Kiteworks | F4: =VLOOKUP(A4,acquisitions!I:K,2,FALSE) -> Active | G4: =IF(F4="active","",VLOOKUP(A4,acquisitions!I:K,3,FALSE)) | H4: =VLOOKUP(A4,public!A:D,2,FALSE) -> No | I4: =VLOOKUP(A4,public!J:K,2,FALSE) -> #N/A | K4: =VLOOKUP(A4,public!A:D,3,FALSE) -> N/A | L4: =VLOOKUP(A4,public!A:D,4,FALSE) -> N/A | M4: 2021 | N4: Not disclosed | O4: Data from universities, companies, governments, clients | P4: Vulnerability in legacy file transfer system | Q4: GDPR | R4: yes | AA4: =COUNTIF(O4,"=*personal*")+COUNTIF(O4,"=*ssn*")++COUNTIF(O4,"=*license*")+COUNTIF(O4,"=*email*")+COUNTIF(O4,"=*vehic*")+COUNTIF(O4,"=*profile*")+COUNTIF(O4,"=*account*")+COUNTIF(O4,"=*image*")+COUNTIF(O4,"=*phone*")+COUNTIF(O4,"=*photo*") -> 0 | AB4: =IF(AA4>0,"yes","") | AC4: =COUNTIF(O4,"=*financ*")+COUNTIF(O4,"=*card*")+COUNTIF(O4,"=*crypto*")+COUNTIF(O4,"=*bank*")+COUNTIF(O4,"=*pay*") -> 0 | AD4: =IF(AC4>0,"yes","") | AE4: =COUNTIF(O4,"=*health*")+COUNTIF(O4,"=*bio*")+COUNTIF(O4,"=*medic*")+COUNTIF(O4,"=*patient*") -> 0 | AF4: =IF(AE4>0,"yes","") | AG4: =COUNTIF(O4,"=*customer*")+COUNTIF(O4,"=*employee*")+COUNTIF(O4,"=*guest*")+COUNTIF(O4,"=*passen*")+COUNTIF(O4,"=*applicant*")+COUNTIF(O4,"=*client*") -> 1 | AH4: =IF(AG4>0,"yes","") -> yes | AI4: =COUNTIF(O4,"=*user*")+COUNTIF(O4,"=*code*")+COUNTIF(O4,"=*software*")+COUNTIF(O4,"=*system*")+COUNTIF(O4,"=*text*")+COUNTIF(O4,"=*api*")+COUNTIF(O4,"=*cyber*") -> 0 | AJ4: =IF(AI4>0,"yes","") | AK4: =COUNTIF(O4,"=*not disclosed*") -> 0 | AL4: =IF(AK4>0,"yes","") | AM4: =IF(C4="yes",D4,"") -> 2021 | AN4: =IF(H4="yes",I4,"") | AO4: =M4 -> 2021 | AP4: =IF(C4="yes",IF(AO4=D4,"same year",IF(AO4<D4,"before",IF(AO4>D4,"after"))),"") -> same year | AQ4: =IF(C4="yes",IF(AP4="before",D4-AO4,IF(AP4="after",AO4-D4,IF(AP4="same year",0))),"") -> 0 | AR4: =IF(H4="yes",IF(AO4=I4,"same year",IF(AO4<I4,"before",IF(AO4>I4,"after"))),"") | AS4: =IF(H4="yes",IF(AR4="same year",0,IF(AR4="before",I4-AO4,IF(AR4="after",AO4-I4))),"") | AT4: =IF(R4="yes",IF(AO4<2018,"before",IF(AO4=2018,"same year",IF(AO4>2018,"after"))),"") -> after | AU4: =IF(R4="yes",IF(AT4="before",2018-AO4,IF(AT4="after",AO4-2018,IF(AT4="same year",0))),"") -> 3 | AV4: =IF(F4="defunct",IF(AO4=G4,"same year",IF(AO4<G4,"before",IF(AO4>=G4,"after"))),"") | AW4: =COUNTIF(P4,"=*vuln*") -> 1 | AX4: =COUNTIF(R4,"=yes") -> 1 | AY4: Accellion | AZ4: =VLOOKUP(A4,certs!U:V,2,FALSE) -> https://www.kiteworks.com/
A5: ACER | B5: =VLOOKUP(A5,industry!A:B,2,FALSE) -> Electronics | C5: =VLOOKUP(A5,acquisitions!A:D,2,FALSE) -> No | D5: =VLOOKUP(A5,acquisitions!A:D,4,FALSE) -> N/A | E5: =VLOOKUP(A5,acquisitions!A:D,3,FALSE) -> N/A | F5: =VLOOKUP(A5,acquisitions!I:K,2,FALSE) -> Active | G5: =IF(F5="active","",VLOOKUP(A5,acquisitions!I:K,3,FALSE)) | H5: =VLOOKUP(A5,public!A:D,2,FALSE) -> Yes | I5: =VLOOKUP(A5,public!J:K,2,FALSE) -> 1988 | J5: =VLOOKUP(A5,'net worth'!B:C,2,FALSE) -> 4100000000 | K5: =VLOOKUP(A5,public!A:D,3,FALSE) -> TWSE | L5: =VLOOKUP(A5,public!A:D,4,FALSE) -> 2353 | M5: 2021 | N5: Unknown | O5: Financial and corporate data | P5: Ransomware | Q5: GDPR | R5: yes | AA5: =COUNTIF(O5,"=*personal*")+COUNTIF(O5,"=*ssn*")++COUNTIF(O5,"=*license*")+COUNTIF(O5,"=*email*")+COUNTIF(O5,"=*vehic*")+COUNTIF(O5,"=*profile*")+COUNTIF(O5,"=*account*")+COUNTIF(O5,"=*image*")+COUNTIF(O5,"=*phone*")+COUNTIF(O5,"=*photo*") -> 0 | AB5: =IF(AA5>0,"yes","") | AC5: =COUNTIF(O5,"=*financ*")+COUNTIF(O5,"=*card*")+COUNTIF(O5,"=*crypto*")+COUNTIF(O5,"=*bank*")+COUNTIF(O5,"=*pay*") -> 1 | AD5: =IF(AC5>0,"yes","") -> yes | AE5: =COUNTIF(O5,"=*health*")+COUNTIF(O5,"=*bio*")+COUNTIF(O5,"=*medic*")+COUNTIF(O5,"=*patient*") -> 0 | AF5: =IF(AE5>0,"yes","") | AG5: =COUNTIF(O5,"=*customer*")+COUNTIF(O5,"=*employee*")+COUNTIF(O5,"=*guest*")+COUNTIF(O5,"=*passen*")+COUNTIF(O5,"=*applicant*")+COUNTIF(O5,"=*client*") -> 0 | AH5: =IF(AG5>0,"yes","") | AI5: =COUNTIF(O5,"=*user*")+COUNTIF(O5,"=*code*")+COUNTIF(O5,"=*software*")+COUNTIF(O5,"=*system*")+COUNTIF(O5,"=*text*")+COUNTIF(O5,"=*api*")+COUNTIF(O5,"=*cyber*") -> 0 | AJ5: =IF(AI5>0,"yes","") | AK5: =COUNTIF(O5,"=*not disclosed*") -> 0 | AL5: =IF(AK5>0,"yes","") | AM5: =IF(C5="yes",D5,"") | AN5: =IF(H5="yes",I5,"") -> 1988 | AO5: =M5 -> 2021 | AP5: =IF(C5="yes",IF(AO5=D5,"same year",IF(AO5<D5,"before",IF(AO5>D5,"after"))),"") | AQ5: =IF(C5="yes",IF(AP5="before",D5-AO5,IF(AP5="after",AO5-D5,IF(AP5="same year",0))),"") | AR5: =IF(H5="yes",IF(AO5=I5,"same year",IF(AO5<I5,"before",IF(AO5>I5,"after"))),"") -> after | AS5: =IF(H5="yes",IF(AR5="same year",0,IF(AR5="before",I5-AO5,IF(AR5="after",AO5-I5))),"") -> 33 | AT5: =IF(R5="yes",IF(AO5<2018,"before",IF(AO5=2018,"same year",IF(AO5>2018,"after"))),"") -> after | AU5: =IF(R5="yes",IF(AT5="before",2018-AO5,IF(AT5="after",AO5-2018,IF(AT5="same year",0))),"") -> 3 | AV5: =IF(F5="defunct",IF(AO5=G5,"same year",IF(AO5<G5,"before",IF(AO5>=G5,"after"))),"") | AW5: =COUNTIF(P5,"=*vuln*") -> 0 | AX5: =COUNTIF(R5,"=yes") -> 1 | AY5: ACER | AZ5: =VLOOKUP(A5,certs!U:V,2,FALSE) -> https://www.acer.com/sustainability/en/esg-governance/information-security-and-privacy-protection/information-security
A6: Aditya Birla Fashion and Retail | B6: =VLOOKUP(A6,industry!A:B,2,FALSE) -> Retail | C6: =VLOOKUP(A6,acquisitions!A:D,2,FALSE) -> No | D6: =VLOOKUP(A6,acquisitions!A:D,4,FALSE) -> N/A | E6: =VLOOKUP(A6,acquisitions!A:D,3,FALSE) -> N/A | F6: =VLOOKUP(A6,acquisitions!I:K,2,FALSE) -> Active | G6: =IF(F6="active","",VLOOKUP(A6,acquisitions!I:K,3,FALSE)) | H6: =VLOOKUP(A6,public!A:D,2,FALSE) -> Yes | I6: =VLOOKUP(A6,public!J:K,2,FALSE) -> 2016 | J6: =VLOOKUP(A6,'net worth'!B:C,2,FALSE) -> 2100000000 | K6: =VLOOKUP(A6,public!A:D,3,FALSE) -> NSE | L6: =VLOOKUP(A6,public!A:D,4,FALSE) -> ABFRL | M6: 2021 | N6: 5400000 | O6: Customer data, contact information | P6: Phishing | Q6: GDPR | R6: yes | AA6: =COUNTIF(O6,"=*personal*")+COUNTIF(O6,"=*ssn*")++COUNTIF(O6,"=*license*")+COUNTIF(O6,"=*email*")+COUNTIF(O6,"=*vehic*")+COUNTIF(O6,"=*profile*")+COUNTIF(O6,"=*account*")+COUNTIF(O6,"=*image*")+COUNTIF(O6,"=*phone*")+COUNTIF(O6,"=*photo*") -> 0 | AB6: =IF(AA6>0,"yes","") | AC6: =COUNTIF(O6,"=*financ*")+COUNTIF(O6,"=*card*")+COUNTIF(O6,"=*crypto*")+COUNTIF(O6,"=*bank*")+COUNTIF(O6,"=*pay*") -> 0 | AD6: =IF(AC6>0,"yes","") | AE6: =COUNTIF(O6,"=*health*")+COUNTIF(O6,"=*bio*")+COUNTIF(O6,"=*medic*")+COUNTIF(O6,"=*patient*") -> 0 | AF6: =IF(AE6>0,"yes","") | AG6: =COUNTIF(O6,"=*customer*")+COUNTIF(O6,"=*employee*")+COUNTIF(O6,"=*guest*")+COUNTIF(O6,"=*passen*")+COUNTIF(O6,"=*applicant*")+COUNTIF(O6,"=*client*") -> 1 | AH6: =IF(AG6>0,"yes","") -> yes | AI6: =COUNTIF(O6,"=*user*")+COUNTIF(O6,"=*code*")+COUNTIF(O6,"=*software*")+COUNTIF(O6,"=*system*")+COUNTIF(O6,"=*text*")+COUNTIF(O6,"=*api*")+COUNTIF(O6,"=*cyber*") -> 0 | AJ6: =IF(AI6>0,"yes","") | AK6: =COUNTIF(O6,"=*not disclosed*") -> 0 | AL6: =IF(AK6>0,"yes","") | AM6: =IF(C6="yes",D6,"") | AN6: =IF(H6="yes",I6,"") -> 2016 | AO6: =M6 -> 2021 | AP6: =IF(C6="yes",IF(AO6=D6,"same year",IF(AO6<D6,"before",IF(AO6>D6,"after"))),"") | AQ6: =IF(C6="yes",IF(AP6="before",D6-AO6,IF(AP6="after",AO6-D6,IF(AP6="same year",0))),"") | AR6: =IF(H6="yes",IF(AO6=I6,"same year",IF(AO6<I6,"before",IF(AO6>I6,"after"))),"") -> after | AS6: =IF(H6="yes",IF(AR6="same year",0,IF(AR6="before",I6-AO6,IF(AR6="after",AO6-I6))),"") -> 5 | AT6: =IF(R6="yes",IF(AO6<2018,"before",IF(AO6=2018,"same year",IF(AO6>2018,"after"))),"") -> after | AU6: =IF(R6="yes",IF(AT6="before",2018-AO6,IF(AT6="after",AO6-2018,IF(AT6="same year",0))),"") -> 3 | AV6: =IF(F6="defunct",IF(AO6=G6,"same year",IF(AO6<G6,"before",IF(AO6>=G6,"after"))),"") | AW6: =COUNTIF(P6,"=*vuln*") -> 0 | AX6: =COUNTIF(R6,"=yes") -> 1 | AY6: Aditya Birla Fashion and Retail | AZ6: =VLOOKUP(A6,certs!U:V,2,FALSE) -> https://www.abfrl.com/corporate-governance/code-of-conduct/
A7: Adobe Creative Cloud | B7: =VLOOKUP(A7,industry!A:B,2,FALSE) -> Technology | C7: =VLOOKUP(A7,acquisitions!A:D,2,FALSE) -> No | D7: =VLOOKUP(A7,acquisitions!A:D,4,FALSE) -> N/A | E7: =VLOOKUP(A7,acquisitions!A:D,3,FALSE) -> N/A | F7: =VLOOKUP(A7,acquisitions!I:K,2,FALSE) -> Active | G7: =IF(F7="active","",VLOOKUP(A7,acquisitions!I:K,3,FALSE)) | H7: =VLOOKUP(A7,public!A:D,2,FALSE) -> Yes | I7: =VLOOKUP(A7,public!J:K,2,FALSE) -> 1986 | J7: =VLOOKUP(A7,'net worth'!B:C,2,FALSE) -> 210500000000 | K7: =VLOOKUP(A7,public!A:D,3,FALSE) -> NASDAQ | L7: =VLOOKUP(A7,public!A:D,4,FALSE) -> ADBE | M7: 2019 | N7: 7500000 | O7: User emails, account information | P7: Database Vulnerability Exploit | Q7: GDPR | R7: yes | AA7: =COUNTIF(O7,"=*personal*")+COUNTIF(O7,"=*ssn*")++COUNTIF(O7,"=*license*")+COUNTIF(O7,"=*email*")+COUNTIF(O7,"=*vehic*")+COUNTIF(O7,"=*profile*")+COUNTIF(O7,"=*account*")+COUNTIF(O7,"=*image*")+COUNTIF(O7,"=*phone*")+COUNTIF(O7,"=*photo*") -> 2 | AB7: =IF(AA7>0,"yes","") -> yes | AC7: =COUNTIF(O7,"=*financ*")+COUNTIF(O7,"=*card*")+COUNTIF(O7,"=*crypto*")+COUNTIF(O7,"=*bank*")+COUNTIF(O7,"=*pay*") -> 0 | AD7: =IF(AC7>0,"yes","") | AE7: =COUNTIF(O7,"=*health*")+COUNTIF(O7,"=*bio*")+COUNTIF(O7,"=*medic*")+COUNTIF(O7,"=*patient*") -> 0 | AF7: =IF(AE7>0,"yes","") | AG7: =COUNTIF(O7,"=*customer*")+COUNTIF(O7,"=*employee*")+COUNTIF(O7,"=*guest*")+COUNTIF(O7,"=*passen*")+COUNTIF(O7,"=*applicant*")+COUNTIF(O7,"=*client*") -> 0 | AH7: =IF(AG7>0,"yes","") | AI7: =COUNTIF(O7,"=*user*")+COUNTIF(O7,"=*code*")+COUNTIF(O7,"=*software*")+COUNTIF(O7,"=*system*")+COUNTIF(O7,"=*text*")+COUNTIF(O7,"=*api*")+COUNTIF(O7,"=*cyber*") -> 1 | AJ7: =IF(AI7>0,"yes","") -> yes | AK7: =COUNTIF(O7,"=*not disclosed*") -> 0 | AL7: =IF(AK7>0,"yes","") | AM7: =IF(C7="yes",D7,"") | AN7: =IF(H7="yes",I7,"") -> 1986 | AO7: =M7 -> 2019 | AP7: =IF(C7="yes",IF(AO7=D7,"same year",IF(AO7<D7,"before",IF(AO7>D7,"after"))),"") | AQ7: =IF(C7="yes",IF(AP7="before",D7-AO7,IF(AP7="after",AO7-D7,IF(AP7="same year",0))),"") | AR7: =IF(H7="yes",IF(AO7=I7,"same year",IF(AO7<I7,"before",IF(AO7>I7,"after"))),"") -> after | AS7: =IF(H7="yes",IF(AR7="same year",0,IF(AR7="before",I7-AO7,IF(AR7="after",AO7-I7))),"") -> 33 | AT7: =IF(R7="yes",IF(AO7<2018,"before",IF(AO7=2018,"same year",IF(AO7>2018,"after"))),"") -> after | AU7: =IF(R7="yes",IF(AT7="before",2018-AO7,IF(AT7="after",AO7-2018,IF(AT7="same year",0))),"") -> 1 | AV7: =IF(F7="defunct",IF(AO7=G7,"same year",IF(AO7<G7,"before",IF(AO7>=G7,"after"))),"") | AW7: =COUNTIF(P7,"=*vuln*") -> 1 | AX7: =COUNTIF(R7,"=yes") -> 1 | AY7: Adobe Creative Cloud | AZ7: =VLOOKUP(A7,certs!U:V,2,FALSE) -> https://www.adobe.com/trust/compliance.html
A8: Adult FriendFinder | B8: =VLOOKUP(A8,industry!A:B,2,FALSE) -> Entertainment | C8: =VLOOKUP(A8,acquisitions!A:D,2,FALSE) -> No | D8: =VLOOKUP(A8,acquisitions!A:D,4,FALSE) -> N/A | E8: =VLOOKUP(A8,acquisitions!A:D,3,FALSE) -> N/A | F8: =VLOOKUP(A8,acquisitions!I:K,2,FALSE) -> Active | G8: =IF(F8="active","",VLOOKUP(A8,acquisitions!I:K,3,FALSE)) | H8: =VLOOKUP(A8,public!A:D,2,FALSE) -> No | I8: =VLOOKUP(A8,public!J:K,2,FALSE) -> #N/A | K8: =VLOOKUP(A8,public!A:D,3,FALSE) -> N/A | L8: =VLOOKUP(A8,public!A:D,4,FALSE) -> N/A | M8: 2018 | N8: 412000000 | O8: User accounts, personal preferences | P8: Unsecured database | Q8: GDPR | R8: yes | AA8: =COUNTIF(O8,"=*personal*")+COUNTIF(O8,"=*ssn*")++COUNTIF(O8,"=*license*")+COUNTIF(O8,"=*email*")+COUNTIF(O8,"=*vehic*")+COUNTIF(O8,"=*profile*")+COUNTIF(O8,"=*account*")+COUNTIF(O8,"=*image*")+COUNTIF(O8,"=*phone*")+COUNTIF(O8,"=*photo*") -> 2 | AB8: =IF(AA8>0,"yes","") -> yes | AC8: =COUNTIF(O8,"=*financ*")+COUNTIF(O8,"=*card*")+COUNTIF(O8,"=*crypto*")+COUNTIF(O8,"=*bank*")+COUNTIF(O8,"=*pay*") -> 0 | AD8: =IF(AC8>0,"yes","") | AE8: =COUNTIF(O8,"=*health*")+COUNTIF(O8,"=*bio*")+COUNTIF(O8,"=*medic*")+COUNTIF(O8,"=*patient*") -> 0 | AF8: =IF(AE8>0,"yes","") | AG8: =COUNTIF(O8,"=*customer*")+COUNTIF(O8,"=*employee*")+COUNTIF(O8,"=*guest*")+COUNTIF(O8,"=*passen*")+COUNTIF(O8,"=*applicant*")+COUNTIF(O8,"=*client*") -> 0 | AH8: =IF(AG8>0,"yes","") | AI8: =COUNTIF(O8,"=*user*")+COUNTIF(O8,"=*code*")+COUNTIF(O8,"=*software*")+COUNTIF(O8,"=*system*")+COUNTIF(O8,"=*text*")+COUNTIF(O8,"=*api*")+COUNTIF(O8,"=*cyber*") -> 1 | AJ8: =IF(AI8>0,"yes","") -> yes | AK8: =COUNTIF(O8,"=*not disclosed*") -> 0 | AL8: =IF(AK8>0,"yes","") | AM8: =IF(C8="yes",D8,"") | AN8: =IF(H8="yes",I8,"") | AO8: =M8 -> 2018 | AP8: =IF(C8="yes",IF(AO8=D8,"same year",IF(AO8<D8,"before",IF(AO8>D8,"after"))),"") | AQ8: =IF(C8="yes",IF(AP8="before",D8-AO8,IF(AP8="after",AO8-D8,IF(AP8="same year",0))),"") | AR8: =IF(H8="yes",IF(AO8=I8,"same year",IF(AO8<I8,"before",IF(AO8>I8,"after"))),"") | AS8: =IF(H8="yes",IF(AR8="same year",0,IF(AR8="before",I8-AO8,IF(AR8="after",AO8-I8))),"") | AT8: =IF(R8="yes",IF(AO8<2018,"before",IF(AO8=2018,"same year",IF(AO8>2018,"after"))),"") -> same year | AU8: =IF(R8="yes",IF(AT8="before",2018-AO8,IF(AT8="after",AO8-2018,IF(AT8="same year",0))),"") -> 0 | AV8: =IF(F8="defunct",IF(AO8=G8,"same year",IF(AO8<G8,"before",IF(AO8>=G8,"after"))),"") | AW8: =COUNTIF(P8,"=*vuln*") -> 0 | AX8: =COUNTIF(R8,"=yes") -> 1 | AY8: Adult FriendFinder | AZ8: =VLOOKUP(A8,certs!U:V,2,FALSE) -> Not Available
A9: Advanced Info Service (AIS) | B9: =VLOOKUP(A9,industry!A:B,2,FALSE) -> Telecommunications | C9: =VLOOKUP(A9,acquisitions!A:D,2,FALSE) -> No | D9: =VLOOKUP(A9,acquisitions!A:D,4,FALSE) -> N/A | E9: =VLOOKUP(A9,acquisitions!A:D,3,FALSE) -> N/A | F9: =VLOOKUP(A9,acquisitions!I:K,2,FALSE) -> Active | G9: =IF(F9="active","",VLOOKUP(A9,acquisitions!I:K,3,FALSE)) | H9: =VLOOKUP(A9,public!A:D,2,FALSE) -> Yes | I9: =VLOOKUP(A9,public!J:K,2,FALSE) -> 1991 | J9: =VLOOKUP(A9,'net worth'!B:C,2,FALSE) -> 13600000000 | K9: =VLOOKUP(A9,public!A:D,3,FALSE) -> SET | L9: =VLOOKUP(A9,public!A:D,4,FALSE) -> ADVANC | M9: 2020 | N9: 8300000000 | O9: DNS query logs, user internet activity | P9: Misconfigured Database | Q9: Thailand PDPA | AA9: =COUNTIF(O9,"=*personal*")+COUNTIF(O9,"=*ssn*")++COUNTIF(O9,"=*license*")+COUNTIF(O9,"=*email*")+COUNTIF(O9,"=*vehic*")+COUNTIF(O9,"=*profile*")+COUNTIF(O9,"=*account*")+COUNTIF(O9,"=*image*")+COUNTIF(O9,"=*phone*")+COUNTIF(O9,"=*photo*") -> 0 | AB9: =IF(AA9>0,"yes","") | AC9: =COUNTIF(O9,"=*financ*")+COUNTIF(O9,"=*card*")+COUNTIF(O9,"=*crypto*")+COUNTIF(O9,"=*bank*")+COUNTIF(O9,"=*pay*") -> 0 | AD9: =IF(AC9>0,"yes","") | AE9: =COUNTIF(O9,"=*health*")+COUNTIF(O9,"=*bio*")+COUNTIF(O9,"=*medic*")+COUNTIF(O9,"=*patient*") -> 0 | AF9: =IF(AE9>0,"yes","") | AG9: =COUNTIF(O9,"=*customer*")+COUNTIF(O9,"=*employee*")+COUNTIF(O9,"=*guest*")+COUNTIF(O9,"=*passen*")+COUNTIF(O9,"=*applicant*")+COUNTIF(O9,"=*client*") -> 0 | AH9: =IF(AG9>0,"yes","") | AI9: =COUNTIF(O9,"=*user*")+COUNTIF(O9,"=*code*")+COUNTIF(O9,"=*software*")+COUNTIF(O9,"=*system*")+COUNTIF(O9,"=*text*")+COUNTIF(O9,"=*api*")+COUNTIF(O9,"=*cyber*") -> 1 | AJ9: =IF(AI9>0,"yes","") -> yes | AK9: =COUNTIF(O9,"=*not disclosed*") -> 0 | AL9: =IF(AK9>0,"yes","") | AM9: =IF(C9="yes",D9,"") | AN9: =IF(H9="yes",I9,"") -> 1991 | AO9: =M9 -> 2020 | AP9: =IF(C9="yes",IF(AO9=D9,"same year",IF(AO9<D9,"before",IF(AO9>D9,"after"))),"") | AQ9: =IF(C9="yes",IF(AP9="before",D9-AO9,IF(AP9="after",AO9-D9,IF(AP9="same year",0))),"") | AR9: =IF(H9="yes",IF(AO9=I9,"same year",IF(AO9<I9,"before",IF(AO9>I9,"after"))),"") -> after | AS9: =IF(H9="yes",IF(AR9="same year",0,IF(AR9="before",I9-AO9,IF(AR9="after",AO9-I9))),"") -> 29 | AT9: =IF(R9="yes",IF(AO9<2018,"before",IF(AO9=2018,"same year",IF(AO9>2018,"after"))),"") | AU9: =IF(R9="yes",IF(AT9="before",2018-AO9,IF(AT9="after",AO9-2018,IF(AT9="same year",0))),"") | AV9: =IF(F9="defunct",IF(AO9=G9,"same year",IF(AO9<G9,"before",IF(AO9>=G9,"after"))),"") | AW9: =COUNTIF(P9,"=*vuln*") -> 0 | AX9: =COUNTIF(R9,"=yes") -> 0 | AY9: Advanced Info Service (AIS) | AZ9: =VLOOKUP(A9,certs!U:V,2,FALSE) -> https://www.ais.co.th/en/compliance.html
A10: Afrihost | B10: =VLOOKUP(A10,industry!A:B,2,FALSE) -> Technology | C10: =VLOOKUP(A10,acquisitions!A:D,2,FALSE) -> No | D10: =VLOOKUP(A10,acquisitions!A:D,4,FALSE) -> N/A | E10: =VLOOKUP(A10,acquisitions!A:D,3,FALSE) -> N/A | F10: =VLOOKUP(A10,acquisitions!I:K,2,FALSE) -> Active | G10: =IF(F10="active","",VLOOKUP(A10,acquisitions!I:K,3,FALSE)) | H10: =VLOOKUP(A10,public!A:D,2,FALSE) -> No | I10: =VLOOKUP(A10,public!J:K,2,FALSE) -> #N/A | K10: =VLOOKUP(A10,public!A:D,3,FALSE) -> N/A | L10: =VLOOKUP(A10,public!A:D,4,FALSE) -> N/A | M10: 2020 | N10: Unknown | O10: Customer data, banking details | P10: Unsecured Database | Q10: POPIA (South Africa), GDPR | R10: yes | AA10: =COUNTIF(O10,"=*personal*")+COUNTIF(O10,"=*ssn*")++COUNTIF(O10,"=*license*")+COUNTIF(O10,"=*email*")+COUNTIF(O10,"=*vehic*")+COUNTIF(O10,"=*profile*")+COUNTIF(O10,"=*account*")+COUNTIF(O10,"=*image*")+COUNTIF(O10,"=*phone*")+COUNTIF(O10,"=*photo*") -> 0 | AB10: =IF(AA10>0,"yes","") | AC10: =COUNTIF(O10,"=*financ*")+COUNTIF(O10,"=*card*")+COUNTIF(O10,"=*crypto*")+COUNTIF(O10,"=*bank*")+COUNTIF(O10,"=*pay*") -> 1 | AD10: =IF(AC10>0,"yes","") -> yes | AE10: =COUNTIF(O10,"=*health*")+COUNTIF(O10,"=*bio*")+COUNTIF(O10,"=*medic*")+COUNTIF(O10,"=*patient*") -> 0 | AF10: =IF(AE10>0,"yes","") | AG10: =COUNTIF(O10,"=*customer*")+COUNTIF(O10,"=*employee*")+COUNTIF(O10,"=*guest*")+COUNTIF(O10,"=*passen*")+COUNTIF(O10,"=*applicant*")+COUNTIF(O10,"=*client*") -> 1 | AH10: =IF(AG10>0,"yes","") -> yes | AI10: =COUNTIF(O10,"=*user*")+COUNTIF(O10,"=*code*")+COUNTIF(O10,"=*software*")+COUNTIF(O10,"=*system*")+COUNTIF(O10,"=*text*")+COUNTIF(O10,"=*api*")+COUNTIF(O10,"=*cyber*") -> 0 | AJ10: =IF(AI10>0,"yes","") | AK10: =COUNTIF(O10,"=*not disclosed*") -> 0 | AL10: =IF(AK10>0,"yes","") | AM10: =IF(C10="yes",D10,"") | AN10: =IF(H10="yes",I10,"") | AO10: =M10 -> 2020 | AP10: =IF(C10="yes",IF(AO10=D10,"same year",IF(AO10<D10,"before",IF(AO10>D10,"after"))),"") | AQ10: =IF(C10="yes",IF(AP10="before",D10-AO10,IF(AP10="after",AO10-D10,IF(AP10="same year",0))),"") | AR10: =IF(H10="yes",IF(AO10=I10,"same year",IF(AO10<I10,"before",IF(AO10>I10,"after"))),"") | AS10: =IF(H10="yes",IF(AR10="same year",0,IF(AR10="before",I10-AO10,IF(AR10="after",AO10-I10))),"") | AT10: =IF(R10="yes",IF(AO10<2018,"before",IF(AO10=2018,"same year",IF(AO10>2018,"after"))),"") -> after | AU10: =IF(R10="yes",IF(AT10="before",2018-AO10,IF(AT10="after",AO10-2018,IF(AT10="same year",0))),"") -> 2 | AV10: =IF(F10="defunct",IF(AO10=G10,"same year",IF(AO10<G10,"before",IF(AO10>=G10,"after"))),"") | AW10: =COUNTIF(P10,"=*vuln*") -> 0 | AX10: =COUNTIF(R10,"=yes") -> 1 | AY10: Afrihost | AZ10: =VLOOKUP(A10,certs!U:V,2,FALSE) -> https://www.afrihost.com/site/page/legal
A11: American Airlines | B11: =VLOOKUP(A11,industry!A:B,2,FALSE) -> Airlines | C11: =VLOOKUP(A11,acquisitions!A:D,2,FALSE) -> No | D11: =VLOOKUP(A11,acquisitions!A:D,4,FALSE) -> N/A | E11: =VLOOKUP(A11,acquisitions!A:D,3,FALSE) -> N/A | F11: =VLOOKUP(A11,acquisitions!I:K,2,FALSE) -> Active | G11: =IF(F11="active","",VLOOKUP(A11,acquisitions!I:K,3,FALSE)) | H11: =VLOOKUP(A11,public!A:D,2,FALSE) -> Yes | I11: =VLOOKUP(A11,public!J:K,2,FALSE) -> 2013 | J11: =VLOOKUP(A11,'net worth'!B:C,2,FALSE) -> 12800000000 | K11: =VLOOKUP(A11,public!A:D,3,FALSE) -> NASDAQ | L11: =VLOOKUP(A11,public!A:D,4,FALSE) -> AAL | M11: 2022 | N11: 1708 | O11: Customer and employee data | P11: Compromised employee accounts | Q11: GDPR | R11: yes | AA11: =COUNTIF(O11,"=*personal*")+COUNTIF(O11,"=*ssn*")++COUNTIF(O11,"=*license*")+COUNTIF(O11,"=*email*")+COUNTIF(O11,"=*vehic*")+COUNTIF(O11,"=*profile*")+COUNTIF(O11,"=*account*")+COUNTIF(O11,"=*image*")+COUNTIF(O11,"=*phone*")+COUNTIF(O11,"=*photo*") -> 0 | AB11: =IF(AA11>0,"yes","") | AC11: =COUNTIF(O11,"=*financ*")+COUNTIF(O11,"=*card*")+COUNTIF(O11,"=*crypto*")+COUNTIF(O11,"=*bank*")+COUNTIF(O11,"=*pay*") -> 0 | AD11: =IF(AC11>0,"yes","") | AE11: =COUNTIF(O11,"=*health*")+COUNTIF(O11,"=*bio*")+COUNTIF(O11,"=*medic*")+COUNTIF(O11,"=*patient*") -> 0 | AF11: =IF(AE11>0,"yes","") | AG11: =COUNTIF(O11,"=*customer*")+COUNTIF(O11,"=*employee*")+COUNTIF(O11,"=*guest*")+COUNTIF(O11,"=*passen*")+COUNTIF(O11,"=*applicant*")+COUNTIF(O11,"=*client*") -> 2 | AH11: =IF(AG11>0,"yes","") -> yes | AI11: =COUNTIF(O11,"=*user*")+COUNTIF(O11,"=*code*")+COUNTIF(O11,"=*software*")+COUNTIF(O11,"=*system*")+COUNTIF(O11,"=*text*")+COUNTIF(O11,"=*api*")+COUNTIF(O11,"=*cyber*") -> 0 | AJ11: =IF(AI11>0,"yes","") | AK11: =COUNTIF(O11,"=*not disclosed*") -> 0 | AL11: =IF(AK11>0,"yes","") | AM11: =IF(C11="yes",D11,"") | AN11: =IF(H11="yes",I11,"") -> 2013 | AO11: =M11 -> 2022 | AP11: =IF(C11="yes",IF(AO11=D11,"same year",IF(AO11<D11,"before",IF(AO11>D11,"after"))),"") | AQ11: =IF(C11="yes",IF(AP11="before",D11-AO11,IF(AP11="after",AO11-D11,IF(AP11="same year",0))),"") | AR11: =IF(H11="yes",IF(AO11=I11,"same year",IF(AO11<I11,"before",IF(AO11>I11,"after"))),"") -> after | AS11: =IF(H11="yes",IF(AR11="same year",0,IF(AR11="before",I11-AO11,IF(AR11="after",AO11-I11))),"") -> 9 | AT11: =IF(R11="yes",IF(AO11<2018,"before",IF(AO11=2018,"same year",IF(AO11>2018,"after"))),"") -> after | AU11: =IF(R11="yes",IF(AT11="before",2018-AO11,IF(AT11="after",AO11-2018,IF(AT11="same year",0))),"") -> 4 | AV11: =IF(F11="defunct",IF(AO11=G11,"same year",IF(AO11<G11,"before",IF(AO11>=G11,"after"))),"") | AW11: =COUNTIF(P11,"=*vuln*") -> 0 | AX11: =COUNTIF(R11,"=yes") -> 1 | AY11: American Airlines | AZ11: =VLOOKUP(A11,certs!U:V,2,FALSE) -> https://www.aa.com/i18n/customer-service/customer-commitment.jsp
A12: Anico | B12: =VLOOKUP(A12,industry!A:B,2,FALSE) -> Insurance | C12: =VLOOKUP(A12,acquisitions!A:D,2,FALSE) -> No | D12: =VLOOKUP(A12,acquisitions!A:D,4,FALSE) -> N/A | E12: =VLOOKUP(A12,acquisitions!A:D,3,FALSE) -> N/A | F12: =VLOOKUP(A12,acquisitions!I:K,2,FALSE) -> Active | G12: =IF(F12="active","",VLOOKUP(A12,acquisitions!I:K,3,FALSE)) | H12: =VLOOKUP(A12,public!A:D,2,FALSE) -> No | I12: =VLOOKUP(A12,public!J:K,2,FALSE) -> #N/A | K12: =VLOOKUP(A12,public!A:D,3,FALSE) -> N/A | L12: =VLOOKUP(A12,public!A:D,4,FALSE) -> N/A | M12: 2023 | N12: 279332 | O12: Names, emails, addresses, SSNs | P12: Phishing | Q12: HIPAA, PCI DSS | T12: yes | W12: yes | AA12: =COUNTIF(O12,"=*personal*")+COUNTIF(O12,"=*ssn*")++COUNTIF(O12,"=*license*")+COUNTIF(O12,"=*email*")+COUNTIF(O12,"=*vehic*")+COUNTIF(O12,"=*profile*")+COUNTIF(O12,"=*account*")+COUNTIF(O12,"=*image*")+COUNTIF(O12,"=*phone*")+COUNTIF(O12,"=*photo*") -> 2 | AB12: =IF(AA12>0,"yes","") -> yes | AC12: =COUNTIF(O12,"=*financ*")+COUNTIF(O12,"=*card*")+COUNTIF(O12,"=*crypto*")+COUNTIF(O12,"=*bank*")+COUNTIF(O12,"=*pay*") -> 0 | AD12: =IF(AC12>0,"yes","") | AE12: =COUNTIF(O12,"=*health*")+COUNTIF(O12,"=*bio*")+COUNTIF(O12,"=*medic*")+COUNTIF(O12,"=*patient*") -> 0 | AF12: =IF(AE12>0,"yes","") | AG12: =COUNTIF(O12,"=*customer*")+COUNTIF(O12,"=*employee*")+COUNTIF(O12,"=*guest*")+COUNTIF(O12,"=*passen*")+COUNTIF(O12,"=*applicant*")+COUNTIF(O12,"=*client*") -> 0 | AH12: =IF(AG12>0,"yes","") | AI12: =COUNTIF(O12,"=*user*")+COUNTIF(O12,"=*code*")+COUNTIF(O12,"=*software*")+COUNTIF(O12,"=*system*")+COUNTIF(O12,"=*text*")+COUNTIF(O12,"=*api*")+COUNTIF(O12,"=*cyber*") -> 0 | AJ12: =IF(AI12>0,"yes","") | AK12: =COUNTIF(O12,"=*not disclosed*") -> 0 | AL12: =IF(AK12>0,"yes","") | AM12: =IF(C12="yes",D12,"") | AN12: =IF(H12="yes",I12,"") | AO12: =M12 -> 2023 | AP12: =IF(C12="yes",IF(AO12=D12,"same year",IF(AO12<D12,"before",IF(AO12>D12,"after"))),"") | AQ12: =IF(C12="yes",IF(AP12="before",D12-AO12,IF(AP12="after",AO12-D12,IF(AP12="same year",0))),"") | AR12: =IF(H12="yes",IF(AO12=I12,"same year",IF(AO12<I12,"before",IF(AO12>I12,"after"))),"") | AS12: =IF(H12="yes",IF(AR12="same year",0,IF(AR12="before",I12-AO12,IF(AR12="after",AO12-I12))),"") | AT12: =IF(R12="yes",IF(AO12<2018,"before",IF(AO12=2018,"same year",IF(AO12>2018,"after"))),"") | AU12: =IF(R12="yes",IF(AT12="before",2018-AO12,IF(AT12="after",AO12-2018,IF(AT12="same year",0))),"") | AV12: =IF(F12="defunct",IF(AO12=G12,"same year",IF(AO12<G12,"before",IF(AO12>=G12,"after"))),"") | AW12: =COUNTIF(P12,"=*vuln*") -> 0 | AX12: =COUNTIF(R12,"=yes") -> 0 | AY12: Anico | AZ12: =VLOOKUP(A12,certs!U:V,2,FALSE) -> https://www.american-national.com/wps/portal/an/home/legal-compliance
A13: Anthem Blue Cross | B13: =VLOOKUP(A13,industry!A:B,2,FALSE) -> Insurance | C13: =VLOOKUP(A13,acquisitions!A:D,2,FALSE) -> Yes | D13: =VLOOKUP(A13,acquisitions!A:D,4,FALSE) -> 2004 | E13: =VLOOKUP(A13,acquisitions!A:D,3,FALSE) -> Anthem, Inc. | F13: =VLOOKUP(A13,acquisitions!I:K,2,FALSE) -> Active | G13: =IF(F13="active","",VLOOKUP(A13,acquisitions!I:K,3,FALSE)) | H13: =VLOOKUP(A13,public!A:D,2,FALSE) -> No | I13: =VLOOKUP(A13,public!J:K,2,FALSE) -> #N/A | K13: =VLOOKUP(A13,public!A:D,3,FALSE) -> N/A | L13: =VLOOKUP(A13,public!A:D,4,FALSE) -> N/A | M13: 2023 | N13: Not disclosed | O13: Names, medical records, SSNs | P13: Ransomware | Q13: HIPAA | W13: yes | AA13: =COUNTIF(O13,"=*personal*")+COUNTIF(O13,"=*ssn*")++COUNTIF(O13,"=*license*")+COUNTIF(O13,"=*email*")+COUNTIF(O13,"=*vehic*")+COUNTIF(O13,"=*profile*")+COUNTIF(O13,"=*account*")+COUNTIF(O13,"=*image*")+COUNTIF(O13,"=*phone*")+COUNTIF(O13,"=*photo*") -> 1 | AB13: =IF(AA13>0,"yes","") -> yes | AC13: =COUNTIF(O13,"=*financ*")+COUNTIF(O13,"=*card*")+COUNTIF(O13,"=*crypto*")+COUNTIF(O13,"=*bank*")+COUNTIF(O13,"=*pay*") -> 0 | AD13: =IF(AC13>0,"yes","") | AE13: =COUNTIF(O13,"=*health*")+COUNTIF(O13,"=*bio*")+COUNTIF(O13,"=*medic*")+COUNTIF(O13,"=*patient*") -> 1 | AF13: =IF(AE13>0,"yes","") -> yes | AG13: =COUNTIF(O13,"=*customer*")+COUNTIF(O13,"=*employee*")+COUNTIF(O13,"=*guest*")+COUNTIF(O13,"=*passen*")+COUNTIF(O13,"=*applicant*")+COUNTIF(O13,"=*client*") -> 0 | AH13: =IF(AG13>0,"yes","") | AI13: =COUNTIF(O13,"=*user*")+COUNTIF(O13,"=*code*")+COUNTIF(O13,"=*software*")+COUNTIF(O13,"=*system*")+COUNTIF(O13,"=*text*")+COUNTIF(O13,"=*api*")+COUNTIF(O13,"=*cyber*") -> 0 | AJ13: =IF(AI13>0,"yes","") | AK13: =COUNTIF(O13,"=*not disclosed*") -> 0 | AL13: =IF(AK13>0,"yes","") | AM13: =IF(C13="yes",D13,"") -> 2004 | AN13: =IF(H13="yes",I13,"") | AO13: =M13 -> 2023 | AP13: =IF(C13="yes",IF(AO13=D13,"same year",IF(AO13<D13,"before",IF(AO13>D13,"after"))),"") -> after | AQ13: =IF(C13="yes",IF(AP13="before",D13-AO13,IF(AP13="after",AO13-D13,IF(AP13="same year",0))),"") -> 19 | AR13: =IF(H13="yes",IF(AO13=I13,"same year",IF(AO13<I13,"before",IF(AO13>I13,"after"))),"") | AS13: =IF(H13="yes",IF(AR13="same year",0,IF(AR13="before",I13-AO13,IF(AR13="after",AO13-I13))),"") | AT13: =IF(R13="yes",IF(AO13<2018,"before",IF(AO13=2018,"same year",IF(AO13>2018,"after"))),"") | AU13: =IF(R13="yes",IF(AT13="before",2018-AO13,IF(AT13="after",AO13-2018,IF(AT13="same year",0))),"") | AV13: =IF(F13="defunct",IF(AO13=G13,"same year",IF(AO13<G13,"before",IF(AO13>=G13,"after"))),"") | AW13: =COUNTIF(P13,"=*vuln*") -> 0 | AX13: =COUNTIF(R13,"=yes") -> 0 | AY13: Anthem Blue Cross | AZ13: =VLOOKUP(A13,certs!U:V,2,FALSE) -> https://www.anthem.com/legal-information
A14: Antheus Tecnologia | B14: =VLOOKUP(A14,industry!A:B,2,FALSE) -> Technology | C14: =VLOOKUP(A14,acquisitions!A:D,2,FALSE) -> Yes | D14: =VLOOKUP(A14,acquisitions!A:D,4,FALSE) -> 2020 | E14: =VLOOKUP(A14,acquisitions!A:D,3,FALSE) -> ISO | F14: =VLOOKUP(A14,acquisitions!I:K,2,FALSE) -> Active | G14: =IF(F14="active","",VLOOKUP(A14,acquisitions!I:K,3,FALSE)) | H14: =VLOOKUP(A14,public!A:D,2,FALSE) -> No | I14: =VLOOKUP(A14,public!J:K,2,FALSE) -> #N/A | K14: =VLOOKUP(A14,public!A:D,3,FALSE) -> N/A | L14: =VLOOKUP(A14,public!A:D,4,FALSE) -> N/A | M14: 2019 | N14: 76000 | O14: Biometric data, fingerprints | P14: Misconfigured Database | Q14: LGPD (Brazil), GDPR | R14: yes | AA14: =COUNTIF(O14,"=*personal*")+COUNTIF(O14,"=*ssn*")++COUNTIF(O14,"=*license*")+COUNTIF(O14,"=*email*")+COUNTIF(O14,"=*vehic*")+COUNTIF(O14,"=*profile*")+COUNTIF(O14,"=*account*")+COUNTIF(O14,"=*image*")+COUNTIF(O14,"=*phone*")+COUNTIF(O14,"=*photo*") -> 0 | AB14: =IF(AA14>0,"yes","") | AC14: =COUNTIF(O14,"=*financ*")+COUNTIF(O14,"=*card*")+COUNTIF(O14,"=*crypto*")+COUNTIF(O14,"=*bank*")+COUNTIF(O14,"=*pay*") -> 0 | AD14: =IF(AC14>0,"yes","") | AE14: =COUNTIF(O14,"=*health*")+COUNTIF(O14,"=*bio*")+COUNTIF(O14,"=*medic*")+COUNTIF(O14,"=*patient*") -> 1 | AF14: =IF(AE14>0,"yes","") -> yes | AG14: =COUNTIF(O14,"=*customer*")+COUNTIF(O14,"=*employee*")+COUNTIF(O14,"=*guest*")+COUNTIF(O14,"=*passen*")+COUNTIF(O14,"=*applicant*")+COUNTIF(O14,"=*client*") -> 0 | AH14: =IF(AG14>0,"yes","") | AI14: =COUNTIF(O14,"=*user*")+COUNTIF(O14,"=*code*")+COUNTIF(O14,"=*software*")+COUNTIF(O14,"=*system*")+COUNTIF(O14,"=*text*")+COUNTIF(O14,"=*api*")+COUNTIF(O14,"=*cyber*") -> 0 | AJ14: =IF(AI14>0,"yes","") | AK14: =COUNTIF(O14,"=*not disclosed*") -> 0 | AL14: =IF(AK14>0,"yes","") | AM14: =IF(C14="yes",D14,"") -> 2020 | AN14: =IF(H14="yes",I14,"") | AO14: =M14 -> 2019 | AP14: =IF(C14="yes",IF(AO14=D14,"same year",IF(AO14<D14,"before",IF(AO14>D14,"after"))),"") -> before | AQ14: =IF(C14="yes",IF(AP14="before",D14-AO14,IF(AP14="after",AO14-D14,IF(AP14="same year",0))),"") -> 1 | AR14: =IF(H14="yes",IF(AO14=I14,"same year",IF(AO14<I14,"before",IF(AO14>I14,"after"))),"") | AS14: =IF(H14="yes",IF(AR14="same year",0,IF(AR14="before",I14-AO14,IF(AR14="after",AO14-I14))),"") | AT14: =IF(R14="yes",IF(AO14<2018,"before",IF(AO14=2018,"same year",IF(AO14>2018,"after"))),"") -> after | AU14: =IF(R14="yes",IF(AT14="before",2018-AO14,IF(AT14="after",AO14-2018,IF(AT14="same year",0))),"") -> 1 | AV14: =IF(F14="defunct",IF(AO14=G14,"same year",IF(AO14<G14,"before",IF(AO14>=G14,"after"))),"") | AW14: =COUNTIF(P14,"=*vuln*") -> 0 | AX14: =COUNTIF(R14,"=yes") -> 1 | AY14: Antheus Tecnologia | AZ14: =VLOOKUP(A14,certs!U:V,2,FALSE) -> https://www.antheustecnologia.com.br/compliance
A15: Apodis Pharma | B15: =VLOOKUP(A15,industry!A:B,2,FALSE) -> Healthcare | C15: =VLOOKUP(A15,acquisitions!A:D,2,FALSE) -> No | D15: =VLOOKUP(A15,acquisitions!A:D,4,FALSE) -> N/A | E15: =VLOOKUP(A15,acquisitions!A:D,3,FALSE) -> N/A | F15: =VLOOKUP(A15,acquisitions!I:K,2,FALSE) -> Active | G15: =IF(F15="active","",VLOOKUP(A15,acquisitions!I:K,3,FALSE)) | H15: =VLOOKUP(A15,public!A:D,2,FALSE) -> No | I15: =VLOOKUP(A15,public!J:K,2,FALSE) -> #N/A | K15: =VLOOKUP(A15,public!A:D,3,FALSE) -> N/A | L15: =VLOOKUP(A15,public!A:D,4,FALSE) -> N/A | M15: 2020 | N15: 1000000 | O15: Customer data, prescription details | P15: Unsecured AWS S3 bucket | Q15: GDPR | R15: yes | AA15: =COUNTIF(O15,"=*personal*")+COUNTIF(O15,"=*ssn*")++COUNTIF(O15,"=*license*")+COUNTIF(O15,"=*email*")+COUNTIF(O15,"=*vehic*")+COUNTIF(O15,"=*profile*")+COUNTIF(O15,"=*account*")+COUNTIF(O15,"=*image*")+COUNTIF(O15,"=*phone*")+COUNTIF(O15,"=*photo*") -> 0 | AB15: =IF(AA15>0,"yes","") | AC15: =COUNTIF(O15,"=*financ*")+COUNTIF(O15,"=*card*")+COUNTIF(O15,"=*crypto*")+COUNTIF(O15,"=*bank*")+COUNTIF(O15,"=*pay*") -> 0 | AD15: =IF(AC15>0,"yes","") | AE15: =COUNTIF(O15,"=*health*")+COUNTIF(O15,"=*bio*")+COUNTIF(O15,"=*medic*")+COUNTIF(O15,"=*patient*") -> 0 | AF15: =IF(AE15>0,"yes","") | AG15: =COUNTIF(O15,"=*customer*")+COUNTIF(O15,"=*employee*")+COUNTIF(O15,"=*guest*")+COUNTIF(O15,"=*passen*")+COUNTIF(O15,"=*applicant*")+COUNTIF(O15,"=*client*") -> 1 | AH15: =IF(AG15>0,"yes","") -> yes | AI15: =COUNTIF(O15,"=*user*")+COUNTIF(O15,"=*code*")+COUNTIF(O15,"=*software*")+COUNTIF(O15,"=*system*")+COUNTIF(O15,"=*text*")+COUNTIF(O15,"=*api*")+COUNTIF(O15,"=*cyber*") -> 0 | AJ15: =IF(AI15>0,"yes","") | AK15: =COUNTIF(O15,"=*not disclosed*") -> 0 | AL15: =IF(AK15>0,"yes","") | AM15: =IF(C15="yes",D15,"") | AN15: =IF(H15="yes",I15,"") | AO15: =M15 -> 2020 | AP15: =IF(C15="yes",IF(AO15=D15,"same year",IF(AO15<D15,"before",IF(AO15>D15,"after"))),"") | AQ15: =IF(C15="yes",IF(AP15="before",D15-AO15,IF(AP15="after",AO15-D15,IF(AP15="same year",0))),"") | AR15: =IF(H15="yes",IF(AO15=I15,"same year",IF(AO15<I15,"before",IF(AO15>I15,"after"))),"") | AS15: =IF(H15="yes",IF(AR15="same year",0,IF(AR15="before",I15-AO15,IF(AR15="after",AO15-I15))),"") | AT15: =IF(R15="yes",IF(AO15<2018,"before",IF(AO15=2018,"same year",IF(AO15>2018,"after"))),"") -> after | AU15: =IF(R15="yes",IF(AT15="before",2018-AO15,IF(AT15="after",AO15-2018,IF(AT15="same year",0))),"") -> 2 | AV15: =IF(F15="defunct",IF(AO15=G15,"same year",IF(AO15<G15,"before",IF(AO15>=G15,"after"))),"") | AW15: =COUNTIF(P15,"=*vuln*") -> 0 | AX15: =COUNTIF(R15,"=yes") -> 1 | AY15: Apodis Pharma | AZ15: =VLOOKUP(A15,certs!U:V,2,FALSE) -> https://www.apodispharma.com/compliance/
